/cluster/work/igp_psr/metzgern/HAC/code/repocode/PopMap2/PopMapEnv/lib64/python3.8/site-packages/sklearn/base.py:318: UserWarning: Trying to unpickle estimator MinMaxScaler from version 1.0.1 when using version 1.2.2. This might lead to breaking code or invalid results. Use at your own risk. For more info please refer to:
https://scikit-learn.org/stable/model_persistence.html#security-maintainability-limitations
  warnings.warn(
/cluster/work/igp_psr/metzgern/HAC/code/repocode/PopMap2/PopMapEnv/lib64/python3.8/site-packages/torch/utils/data/dataloader.py:554: UserWarning: This DataLoader will create 10 worker processes in total. Our suggested max number of worker in current system is 4, which is smaller than what this DataLoader is going to create. Please be aware that excessive worker creation might get DataLoader running slow or even freeze, lower the worker number to avoid potential slowness/freeze if necessary.
  warnings.warn(_create_warning_msg(
wandb: Currently logged in as: nandometzger. Use `wandb login --relogin` to force relogin
wandb: Tracking run with wandb version 0.14.0
wandb: Run data is saved locally in /cluster/work/igp_psr/metzgern/HAC/code/PopMapResults/So2Sat/experiment_2_318/wandb/run-20230328_071858-md8rxife
wandb: Run `wandb offline` to turn off syncing.
wandb: Syncing run revived-forest-410
wandb: ‚≠êÔ∏è View project at https://wandb.ai/nandometzger/POMELOv2
wandb: üöÄ View run at https://wandb.ai/nandometzger/POMELOv2/runs/md8rxife
Command Line Args:   --no-osm --satmode --num_epochs 100 --lam_builtmask 0.0 --batch_size 384 --lr_step 10 -lr 3e-4 --lr_step 15 --lr_gamma 0.75 --model JacobsUNet --feature_extractor vgg11 --loss l1_loss --lam 1000 --lam_adv 100.0 -S2 --feature_dim 16 --random_season --target_region pri2017 --adversarial --save-dir /cluster/work/igp_psr/metzgern/HAC/code/PopMapResults --head v1 --classifier v2
Defaults:
  --dataset:         So2Sat
  --target_regions:  []
  --weightdecay:     0.0
  --lassoreg:        0.0
  --tv:              0.0
  --gradient_clip:   0.01
  --lam_dense:       1.0
  --num_workers:     10
  --wandb_project:   POMELOv2
  --logstep_train:   20
  --val_every_n_epochs:1
  --seed:            1610
  --save-model:      both
  --max_samples:     1000000000000000.0

Model JacobsUNet ; #Params: 14494997
  0%|          | 0/100 [00:00<?, ?it/s]  0%|          | 0/100 [00:00<?, ?it/s, best_validation_loss=nan, training_loss=nan, validation_loss=nan]
  0%|          | 0/496 [00:00<?, ?it/s][A
  0%|          | 0/496 [00:00<?, ?it/s, training_loss=nan][A/cluster/work/igp_psr/metzgern/HAC/code/repocode/PopMap2/PopMapEnv/lib64/python3.8/site-packages/torch/utils/data/dataloader.py:554: UserWarning: This DataLoader will create 10 worker processes in total. Our suggested max number of worker in current system is 4, which is smaller than what this DataLoader is going to create. Please be aware that excessive worker creation might get DataLoader running slow or even freeze, lower the worker number to avoid potential slowness/freeze if necessary.
  warnings.warn(_create_warning_msg(

                                                          [A  0%|          | 0/100 [00:03<?, ?it/s, best_validation_loss=nan, training_loss=nan, validation_loss=nan]
wandb: Waiting for W&B process to finish... (failed 1). Press Control-C to abort syncing.
wandb: üöÄ View run revived-forest-410 at: https://wandb.ai/nandometzger/POMELOv2/runs/md8rxife
wandb: Synced 6 W&B file(s), 0 media file(s), 3 artifact file(s) and 1 other file(s)
wandb: Find logs at: /cluster/work/igp_psr/metzgern/HAC/code/PopMapResults/So2Sat/experiment_2_318/wandb/run-20230328_071858-md8rxife/logs
Traceback (most recent call last):
  File "run_train.py", line 495, in <module>
    trainer.train()
  File "run_train.py", line 116, in train
    self.train_epoch(tnr)
  File "run_train.py", line 157, in train_epoch
    for i, sample in enumerate(inner_tnr):
  File "/cluster/work/igp_psr/metzgern/HAC/code/repocode/PopMap2/PopMapEnv/lib64/python3.8/site-packages/tqdm/std.py", line 1178, in __iter__
    for obj in iterable:
  File "/cluster/work/igp_psr/metzgern/HAC/code/repocode/PopMap2/PopMapEnv/lib64/python3.8/site-packages/torch/utils/data/dataloader.py", line 628, in __next__
    data = self._next_data()
  File "/cluster/work/igp_psr/metzgern/HAC/code/repocode/PopMap2/PopMapEnv/lib64/python3.8/site-packages/torch/utils/data/dataloader.py", line 1333, in _next_data
    return self._process_data(data)
  File "/cluster/work/igp_psr/metzgern/HAC/code/repocode/PopMap2/PopMapEnv/lib64/python3.8/site-packages/torch/utils/data/dataloader.py", line 1359, in _process_data
    data.reraise()
  File "/cluster/work/igp_psr/metzgern/HAC/code/repocode/PopMap2/PopMapEnv/lib64/python3.8/site-packages/torch/_utils.py", line 543, in reraise
    raise exception
rasterio.errors.RasterioIOError: Caught RasterioIOError in DataLoader worker process 0.
Original Traceback (most recent call last):
  File "rasterio/_base.pyx", line 308, in rasterio._base.DatasetBase.__init__
  File "rasterio/_base.pyx", line 219, in rasterio._base.open_dataset
  File "rasterio/_err.pyx", line 221, in rasterio._err.exc_wrap_pointer
rasterio._err.CPLE_OpenFailedError: /scratch/metzgern/HAC/data/So2Sat_POP_Part1/train/00179_22835_birmingham/sen2summer/Class_11/1kmN3322E3525_sen2summer.tif: No such file or directory

During handling of the above exception, another exception occurred:

Traceback (most recent call last):
  File "/cluster/work/igp_psr/metzgern/HAC/code/repocode/PopMap2/PopMapEnv/lib64/python3.8/site-packages/torch/utils/data/_utils/worker.py", line 302, in _worker_loop
    data = fetcher.fetch(index)
  File "/cluster/work/igp_psr/metzgern/HAC/code/repocode/PopMap2/PopMapEnv/lib64/python3.8/site-packages/torch/utils/data/_utils/fetch.py", line 58, in fetch
    data = [self.dataset[idx] for idx in possibly_batched_index]
  File "/cluster/work/igp_psr/metzgern/HAC/code/repocode/PopMap2/PopMapEnv/lib64/python3.8/site-packages/torch/utils/data/_utils/fetch.py", line 58, in <listcomp>
    data = [self.dataset[idx] for idx in possibly_batched_index]
  File "/cluster/work/igp_psr/metzgern/HAC/code/repocode/PopMap2/data/So2Sat.py", line 92, in __getitem__
    X, Pop_X, PopNN_X, pop_avail, msb, msb_avail = self.data_generation(ID_temp)
  File "/cluster/work/igp_psr/metzgern/HAC/code/repocode/PopMap2/data/So2Sat.py", line 170, in data_generation
    data.append(self.generate_data(ID_sen2, channels=3, data='sen2spring'))
  File "/cluster/work/igp_psr/metzgern/HAC/code/repocode/PopMap2/data/So2Sat.py", line 216, in generate_data
    with rasterio.open(ID_temp, 'r') as ds:
  File "/cluster/work/igp_psr/metzgern/HAC/code/repocode/PopMap2/PopMapEnv/lib64/python3.8/site-packages/rasterio/env.py", line 451, in wrapper
    return f(*args, **kwds)
  File "/cluster/work/igp_psr/metzgern/HAC/code/repocode/PopMap2/PopMapEnv/lib64/python3.8/site-packages/rasterio/__init__.py", line 304, in open
    dataset = DatasetReader(path, driver=driver, sharing=sharing, **kwargs)
  File "rasterio/_base.pyx", line 310, in rasterio._base.DatasetBase.__init__
rasterio.errors.RasterioIOError: /scratch/metzgern/HAC/data/So2Sat_POP_Part1/train/00179_22835_birmingham/sen2summer/Class_11/1kmN3322E3525_sen2summer.tif: No such file or directory

